2023-10-22 22:28:31,900 INFO    StreamThr :14452 [internal.py:wandb_internal():86] W&B internal server running at pid: 14452, started at: 2023-10-22 22:28:31.899837
2023-10-22 22:28:31,902 DEBUG   HandlerThread:14452 [handler.py:handle_request():144] handle_request: status
2023-10-22 22:28:31,914 INFO    WriterThread:14452 [datastore.py:open_for_write():85] open: /home/xuanming/kaggle/google_runtime/torch/GST/wandb/run-20231022_222831-mhk7yqxt/run-mhk7yqxt.wandb
2023-10-22 22:28:31,914 DEBUG   SenderThread:14452 [sender.py:send():379] send: header
2023-10-22 22:28:31,922 DEBUG   SenderThread:14452 [sender.py:send():379] send: run
2023-10-22 22:28:32,622 ERROR   SenderThread:14452 [internal_api.py:execute():361] 403 response executing GraphQL.
2023-10-22 22:28:32,622 ERROR   SenderThread:14452 [internal_api.py:execute():362] {"errors":[{"message":"permission denied","path":["upsertBucket"],"extensions":{"code":"PERMISSION_ERROR"}}],"data":{"upsertBucket":null}}
2023-10-22 22:28:32,622 ERROR   SenderThread:14452 [sender.py:send_run():976] It appears that you do not have permission to access the requested resource. Please reach out to the project owner to grant you access. If you have the correct permissions, verify that there are no issues with your networking setup.(Error 403: Forbidden)
Traceback (most recent call last):
  File "/home/xuanming/.local/lib/python3.11/site-packages/wandb/sdk/lib/retry.py", line 131, in __call__
    result = self._call_fn(*args, **kwargs)
             ^^^^^^^^^^^^^^^^^^^^^^^^^^^^^^
  File "/home/xuanming/.local/lib/python3.11/site-packages/wandb/sdk/internal/internal_api.py", line 358, in execute
    return self.client.execute(*args, **kwargs)  # type: ignore
           ^^^^^^^^^^^^^^^^^^^^^^^^^^^^^^^^^^^^
  File "/home/xuanming/.local/lib/python3.11/site-packages/wandb/vendor/gql-0.2.0/wandb_gql/client.py", line 52, in execute
    result = self._get_result(document, *args, **kwargs)
             ^^^^^^^^^^^^^^^^^^^^^^^^^^^^^^^^^^^^^^^^^^^
  File "/home/xuanming/.local/lib/python3.11/site-packages/wandb/vendor/gql-0.2.0/wandb_gql/client.py", line 60, in _get_result
    return self.transport.execute(document, *args, **kwargs)
           ^^^^^^^^^^^^^^^^^^^^^^^^^^^^^^^^^^^^^^^^^^^^^^^^^
  File "/home/xuanming/.local/lib/python3.11/site-packages/wandb/sdk/lib/gql_request.py", line 56, in execute
    request.raise_for_status()
  File "/home/xuanming/.local/lib/python3.11/site-packages/requests/models.py", line 1021, in raise_for_status
    raise HTTPError(http_error_msg, response=self)
requests.exceptions.HTTPError: 403 Client Error: Forbidden for url: https://api.wandb.ai/graphql

During handling of the above exception, another exception occurred:

Traceback (most recent call last):
  File "/home/xuanming/.local/lib/python3.11/site-packages/wandb/sdk/internal/sender.py", line 974, in send_run
    self._init_run(run, config_value_dict)
  File "/home/xuanming/.local/lib/python3.11/site-packages/wandb/sdk/internal/sender.py", line 1012, in _init_run
    server_run, inserted, server_messages = self._api.upsert_run(
                                            ^^^^^^^^^^^^^^^^^^^^^
  File "/home/xuanming/.local/lib/python3.11/site-packages/wandb/apis/normalize.py", line 73, in wrapper
    raise err
  File "/home/xuanming/.local/lib/python3.11/site-packages/wandb/apis/normalize.py", line 41, in wrapper
    return func(*args, **kwargs)
           ^^^^^^^^^^^^^^^^^^^^^
  File "/home/xuanming/.local/lib/python3.11/site-packages/wandb/sdk/internal/internal_api.py", line 1999, in upsert_run
    response = self.gql(
               ^^^^^^^^^
  File "/home/xuanming/.local/lib/python3.11/site-packages/wandb/sdk/internal/internal_api.py", line 330, in gql
    ret = self._retry_gql(
          ^^^^^^^^^^^^^^^^
  File "/home/xuanming/.local/lib/python3.11/site-packages/wandb/sdk/lib/retry.py", line 147, in __call__
    retry_timedelta_triggered = check_retry_fn(e)
                                ^^^^^^^^^^^^^^^^^
  File "/home/xuanming/.local/lib/python3.11/site-packages/wandb/util.py", line 964, in check_retry_fn
    return fallback_retry_fn(e)
           ^^^^^^^^^^^^^^^^^^^^
  File "/home/xuanming/.local/lib/python3.11/site-packages/wandb/util.py", line 906, in no_retry_auth
    raise CommError(
wandb.errors.CommError: It appears that you do not have permission to access the requested resource. Please reach out to the project owner to grant you access. If you have the correct permissions, verify that there are no issues with your networking setup.(Error 403: Forbidden)
2023-10-22 22:28:37,629 DEBUG   HandlerThread:14452 [handler.py:handle_request():144] handle_request: status_report
2023-10-22 22:28:42,629 DEBUG   HandlerThread:14452 [handler.py:handle_request():144] handle_request: status_report
2023-10-22 22:28:47,630 DEBUG   HandlerThread:14452 [handler.py:handle_request():144] handle_request: status_report
2023-10-22 22:28:52,631 DEBUG   HandlerThread:14452 [handler.py:handle_request():144] handle_request: status_report
2023-10-22 22:28:57,631 DEBUG   HandlerThread:14452 [handler.py:handle_request():144] handle_request: status_report
2023-10-22 22:29:02,632 DEBUG   HandlerThread:14452 [handler.py:handle_request():144] handle_request: status_report
2023-10-22 22:29:07,632 DEBUG   HandlerThread:14452 [handler.py:handle_request():144] handle_request: status_report
2023-10-22 22:29:12,633 DEBUG   HandlerThread:14452 [handler.py:handle_request():144] handle_request: status_report
2023-10-22 22:29:17,633 DEBUG   HandlerThread:14452 [handler.py:handle_request():144] handle_request: status_report
2023-10-22 22:29:22,634 DEBUG   HandlerThread:14452 [handler.py:handle_request():144] handle_request: status_report
2023-10-22 22:29:27,635 DEBUG   HandlerThread:14452 [handler.py:handle_request():144] handle_request: status_report
2023-10-22 22:29:32,635 DEBUG   HandlerThread:14452 [handler.py:handle_request():144] handle_request: status_report
2023-10-22 22:29:37,636 DEBUG   HandlerThread:14452 [handler.py:handle_request():144] handle_request: status_report
2023-10-22 22:29:42,636 DEBUG   HandlerThread:14452 [handler.py:handle_request():144] handle_request: status_report
2023-10-22 22:29:47,637 DEBUG   HandlerThread:14452 [handler.py:handle_request():144] handle_request: status_report
2023-10-22 22:29:52,638 DEBUG   HandlerThread:14452 [handler.py:handle_request():144] handle_request: status_report
2023-10-22 22:29:57,638 DEBUG   HandlerThread:14452 [handler.py:handle_request():144] handle_request: status_report
2023-10-22 22:30:02,639 DEBUG   HandlerThread:14452 [handler.py:handle_request():144] handle_request: status_report
2023-10-22 22:30:07,639 DEBUG   HandlerThread:14452 [handler.py:handle_request():144] handle_request: status_report
2023-10-22 22:30:12,640 DEBUG   HandlerThread:14452 [handler.py:handle_request():144] handle_request: status_report
2023-10-22 22:30:17,641 DEBUG   HandlerThread:14452 [handler.py:handle_request():144] handle_request: status_report
2023-10-22 22:30:22,641 DEBUG   HandlerThread:14452 [handler.py:handle_request():144] handle_request: status_report
2023-10-22 22:30:27,642 DEBUG   HandlerThread:14452 [handler.py:handle_request():144] handle_request: status_report
2023-10-22 22:30:29,787 DEBUG   HandlerThread:14452 [handler.py:handle_request():144] handle_request: shutdown
2023-10-22 22:30:29,788 INFO    HandlerThread:14452 [handler.py:finish():840] shutting down handler
2023-10-22 22:30:30,645 INFO    SenderThread:14452 [sender.py:finish():1531] shutting down sender
2023-10-22 22:30:30,645 INFO    WriterThread:14452 [datastore.py:close():294] close: /home/xuanming/kaggle/google_runtime/torch/GST/wandb/run-20231022_222831-mhk7yqxt/run-mhk7yqxt.wandb
